Failure # 1 (occurred at 2024-02-25_11-47-01)
Traceback (most recent call last):
  File "/home/cail005/anaconda3/envs/marl/lib/python3.8/site-packages/ray/tune/trial_runner.py", line 890, in _process_trial
    results = self.trial_executor.fetch_result(trial)
  File "/home/cail005/anaconda3/envs/marl/lib/python3.8/site-packages/ray/tune/ray_trial_executor.py", line 788, in fetch_result
    result = ray.get(trial_future[0], timeout=DEFAULT_GET_TIMEOUT)
  File "/home/cail005/anaconda3/envs/marl/lib/python3.8/site-packages/ray/_private/client_mode_hook.py", line 105, in wrapper
    return func(*args, **kwargs)
  File "/home/cail005/anaconda3/envs/marl/lib/python3.8/site-packages/ray/worker.py", line 1625, in get
    raise value.as_instanceof_cause()
ray.exceptions.RayTaskError(IndexError): [36mray::MAPPOTrainer.train()[39m (pid=8220, ip=10.33.1.26, repr=MAPPOTrainer)
  File "/home/cail005/anaconda3/envs/marl/lib/python3.8/site-packages/ray/rllib/agents/trainer.py", line 679, in train
    raise e
  File "/home/cail005/anaconda3/envs/marl/lib/python3.8/site-packages/ray/rllib/agents/trainer.py", line 668, in train
    result = Trainable.train(self)
  File "/home/cail005/anaconda3/envs/marl/lib/python3.8/site-packages/ray/tune/trainable.py", line 283, in train
    result = self.step()
  File "/home/cail005/anaconda3/envs/marl/lib/python3.8/site-packages/ray/rllib/agents/trainer_template.py", line 206, in step
    step_results = next(self.train_exec_impl)
  File "/home/cail005/anaconda3/envs/marl/lib/python3.8/site-packages/ray/util/iter.py", line 756, in __next__
    return next(self.built_iterator)
  File "/home/cail005/anaconda3/envs/marl/lib/python3.8/site-packages/ray/util/iter.py", line 783, in apply_foreach
    for item in it:
  File "/home/cail005/anaconda3/envs/marl/lib/python3.8/site-packages/ray/util/iter.py", line 783, in apply_foreach
    for item in it:
  File "/home/cail005/anaconda3/envs/marl/lib/python3.8/site-packages/ray/util/iter.py", line 843, in apply_filter
    for item in it:
  File "/home/cail005/anaconda3/envs/marl/lib/python3.8/site-packages/ray/util/iter.py", line 843, in apply_filter
    for item in it:
  File "/home/cail005/anaconda3/envs/marl/lib/python3.8/site-packages/ray/util/iter.py", line 783, in apply_foreach
    for item in it:
  File "/home/cail005/anaconda3/envs/marl/lib/python3.8/site-packages/ray/util/iter.py", line 783, in apply_foreach
    for item in it:
  File "/home/cail005/anaconda3/envs/marl/lib/python3.8/site-packages/ray/util/iter.py", line 783, in apply_foreach
    for item in it:
  [Previous line repeated 1 more time]
  File "/home/cail005/anaconda3/envs/marl/lib/python3.8/site-packages/ray/util/iter.py", line 876, in apply_flatten
    for item in it:
  File "/home/cail005/anaconda3/envs/marl/lib/python3.8/site-packages/ray/util/iter.py", line 783, in apply_foreach
    for item in it:
  File "/home/cail005/anaconda3/envs/marl/lib/python3.8/site-packages/ray/util/iter.py", line 783, in apply_foreach
    for item in it:
  File "/home/cail005/anaconda3/envs/marl/lib/python3.8/site-packages/ray/util/iter.py", line 783, in apply_foreach
    for item in it:
  [Previous line repeated 1 more time]
  File "/home/cail005/anaconda3/envs/marl/lib/python3.8/site-packages/ray/util/iter.py", line 471, in base_iterator
    yield ray.get(futures, timeout=timeout)
ray.exceptions.RayTaskError(IndexError): [36mray::RolloutWorker.par_iter_next()[39m (pid=8220, ip=10.33.1.26, repr=<ray.rllib.evaluation.rollout_worker.modify_class.<locals>.Class object at 0x7f5e89e621c0>)
  File "/home/cail005/anaconda3/envs/marl/lib/python3.8/site-packages/ray/util/iter.py", line 1151, in par_iter_next
    return next(self.local_it)
  File "/home/cail005/anaconda3/envs/marl/lib/python3.8/site-packages/ray/rllib/evaluation/rollout_worker.py", line 378, in gen_rollouts
    yield self.sample()
  File "/home/cail005/anaconda3/envs/marl/lib/python3.8/site-packages/ray/rllib/evaluation/rollout_worker.py", line 753, in sample
    batches = [self.input_reader.next()]
  File "/home/cail005/anaconda3/envs/marl/lib/python3.8/site-packages/ray/rllib/evaluation/sampler.py", line 103, in next
    batches = [self.get_data()]
  File "/home/cail005/anaconda3/envs/marl/lib/python3.8/site-packages/ray/rllib/evaluation/sampler.py", line 233, in get_data
    item = next(self._env_runner)
  File "/home/cail005/anaconda3/envs/marl/lib/python3.8/site-packages/ray/rllib/evaluation/sampler.py", line 586, in _env_runner
    base_env.poll()
  File "/home/cail005/anaconda3/envs/marl/lib/python3.8/site-packages/ray/rllib/env/base_env.py", line 422, in poll
    obs[i], rewards[i], dones[i], infos[i] = env_state.poll()
  File "/home/cail005/anaconda3/envs/marl/lib/python3.8/site-packages/ray/rllib/env/base_env.py", line 478, in poll
    self.reset()
  File "/home/cail005/anaconda3/envs/marl/lib/python3.8/site-packages/ray/rllib/env/base_env.py", line 528, in reset
    self.last_obs = self.env.reset()
  File "run.py", line 66, in reset
    obs[name] = {"obs": np.array(original_obs[i])}
IndexError: list index out of range

