Failure # 1 (occurred at 2023-12-18_15-14-45)
Traceback (most recent call last):
  File "/home/cail005/anaconda3/envs/marl/lib/python3.8/site-packages/ray/tune/trial_runner.py", line 890, in _process_trial
    results = self.trial_executor.fetch_result(trial)
  File "/home/cail005/anaconda3/envs/marl/lib/python3.8/site-packages/ray/tune/ray_trial_executor.py", line 788, in fetch_result
    result = ray.get(trial_future[0], timeout=DEFAULT_GET_TIMEOUT)
  File "/home/cail005/anaconda3/envs/marl/lib/python3.8/site-packages/ray/_private/client_mode_hook.py", line 105, in wrapper
    return func(*args, **kwargs)
  File "/home/cail005/anaconda3/envs/marl/lib/python3.8/site-packages/ray/worker.py", line 1625, in get
    raise value.as_instanceof_cause()
ray.exceptions.RayTaskError(AttributeError): [36mray::IQL.train()[39m (pid=63712, ip=10.33.1.26, repr=IQL)
  File "/home/cail005/anaconda3/envs/marl/lib/python3.8/site-packages/ray/rllib/agents/trainer.py", line 682, in train
    raise e
  File "/home/cail005/anaconda3/envs/marl/lib/python3.8/site-packages/ray/rllib/agents/trainer.py", line 668, in train
    result = Trainable.train(self)
  File "/home/cail005/anaconda3/envs/marl/lib/python3.8/site-packages/ray/tune/trainable.py", line 283, in train
    result = self.step()
  File "/home/cail005/anaconda3/envs/marl/lib/python3.8/site-packages/ray/rllib/agents/trainer_template.py", line 206, in step
    step_results = next(self.train_exec_impl)
  File "/home/cail005/anaconda3/envs/marl/lib/python3.8/site-packages/ray/util/iter.py", line 756, in __next__
    return next(self.built_iterator)
  File "/home/cail005/anaconda3/envs/marl/lib/python3.8/site-packages/ray/util/iter.py", line 783, in apply_foreach
    for item in it:
  File "/home/cail005/anaconda3/envs/marl/lib/python3.8/site-packages/ray/util/iter.py", line 843, in apply_filter
    for item in it:
  File "/home/cail005/anaconda3/envs/marl/lib/python3.8/site-packages/ray/util/iter.py", line 843, in apply_filter
    for item in it:
  File "/home/cail005/anaconda3/envs/marl/lib/python3.8/site-packages/ray/util/iter.py", line 783, in apply_foreach
    for item in it:
  File "/home/cail005/anaconda3/envs/marl/lib/python3.8/site-packages/ray/util/iter.py", line 843, in apply_filter
    for item in it:
  File "/home/cail005/anaconda3/envs/marl/lib/python3.8/site-packages/ray/util/iter.py", line 1075, in build_union
    item = next(it)
  File "/home/cail005/anaconda3/envs/marl/lib/python3.8/site-packages/ray/util/iter.py", line 756, in __next__
    return next(self.built_iterator)
  File "/home/cail005/anaconda3/envs/marl/lib/python3.8/site-packages/ray/util/iter.py", line 783, in apply_foreach
    for item in it:
  File "/home/cail005/anaconda3/envs/marl/lib/python3.8/site-packages/ray/util/iter.py", line 783, in apply_foreach
    for item in it:
  File "/home/cail005/anaconda3/envs/marl/lib/python3.8/site-packages/ray/util/iter.py", line 791, in apply_foreach
    result = fn(item)
  File "/home/cail005/anaconda3/envs/marl/lib/python3.8/site-packages/ray/rllib/execution/train_ops.py", line 95, in __call__
    self.workers.local_worker().learn_on_batch(batch)
  File "/home/cail005/anaconda3/envs/marl/lib/python3.8/site-packages/ray/rllib/evaluation/rollout_worker.py", line 958, in learn_on_batch
    info_out[pid] = policy.learn_on_batch(batch)
  File "/home/cail005/Documents/nZEC/MARLlib/marllib/marl/algos/core/VD/iql_vdn_qmix.py", line 349, in learn_on_batch
    chop_into_sequences(
  File "/home/cail005/anaconda3/envs/marl/lib/python3.8/site-packages/ray/rllib/policy/rnn_sequencing.py", line 301, in chop_into_sequences
    if f.dtype == np.object or f.dtype.type is np.str_:
  File "/home/cail005/anaconda3/envs/marl/lib/python3.8/site-packages/numpy/__init__.py", line 305, in __getattr__
    raise AttributeError(__former_attrs__[attr])
AttributeError: module 'numpy' has no attribute 'object'.
`np.object` was a deprecated alias for the builtin `object`. To avoid this error in existing code, use `object` by itself. Doing this will not modify any behavior and is safe. 
The aliases was originally deprecated in NumPy 1.20; for more details and guidance see the original release note at:
    https://numpy.org/devdocs/release/1.20.0-notes.html#deprecations

